Traceback (most recent call last):
  File "/home/runner/workspace/manage.py", line 22, in <module>
    main()
  File "/home/runner/workspace/manage.py", line 18, in main
    execute_from_command_line(sys.argv)
  File "/home/runner/workspace/.pythonlibs/lib/python3.12/site-packages/django/core/management/__init__.py", line 442, in execute_from_command_line
    utility.execute()
  File "/home/runner/workspace/.pythonlibs/lib/python3.12/site-packages/django/core/management/__init__.py", line 436, in execute
    self.fetch_command(subcommand).run_from_argv(self.argv)
  File "/home/runner/workspace/.pythonlibs/lib/python3.12/site-packages/django/core/management/base.py", line 416, in run_from_argv
    self.execute(*args, **cmd_options)
  File "/home/runner/workspace/.pythonlibs/lib/python3.12/site-packages/django/core/management/base.py", line 460, in execute
    output = self.handle(*args, **options)
             ^^^^^^^^^^^^^^^^^^^^^^^^^^^^^
  File "/home/runner/workspace/.pythonlibs/lib/python3.12/site-packages/django/core/management/base.py", line 107, in wrapper
    res = handle_func(*args, **kwargs)
          ^^^^^^^^^^^^^^^^^^^^^^^^^^^^
  File "/home/runner/workspace/.pythonlibs/lib/python3.12/site-packages/django/core/management/commands/migrate.py", line 114, in handle
    executor = MigrationExecutor(connection, self.migration_progress_callback)
               ^^^^^^^^^^^^^^^^^^^^^^^^^^^^^^^^^^^^^^^^^^^^^^^^^^^^^^^^^^^^^^^
  File "/home/runner/workspace/.pythonlibs/lib/python3.12/site-packages/django/db/migrations/executor.py", line 18, in __init__
    self.loader = MigrationLoader(self.connection)
                  ^^^^^^^^^^^^^^^^^^^^^^^^^^^^^^^^
  File "/home/runner/workspace/.pythonlibs/lib/python3.12/site-packages/django/db/migrations/loader.py", line 58, in __init__
    self.build_graph()
  File "/home/runner/workspace/.pythonlibs/lib/python3.12/site-packages/django/db/migrations/loader.py", line 276, in build_graph
    self.graph.validate_consistency()
  File "/home/runner/workspace/.pythonlibs/lib/python3.12/site-packages/django/db/migrations/graph.py", line 198, in validate_consistency
    [n.raise_error() for n in self.node_map.values() if isinstance(n, DummyNode)]
     ^^^^^^^^^^^^^^^
  File "/home/runner/workspace/.pythonlibs/lib/python3.12/site-packages/django/db/migrations/graph.py", line 60, in raise_error
    raise NodeNotFoundError(self.error_message, self.key, origin=self.origin)
django.db.migrations.exceptions.NodeNotFoundError: Migration doctor.0012_merge_20220909_1257 dependencies reference nonexistent parent node ('doctor', '0009_prescription_extra_information')
~/workspace$ 