
Exception in thread django-main-thread:
Traceback (most recent call last):
  File "/nix/store/vnvdzw4182wb2ifzi0cczhv80yfnpx1q-python3-3.12.11/lib/python3.12/threading.py", line 1075, in _bootstrap_inner
    self.run()
  File "/nix/store/vnvdzw4182wb2ifzi0cczhv80yfnpx1q-python3-3.12.11/lib/python3.12/threading.py", line 1012, in run
    self._target(*self._args, **self._kwargs)
  File "/home/runner/workspace/.pythonlibs/lib/python3.12/site-packages/django/utils/autoreload.py", line 64, in wrapper
    fn(*args, **kwargs)
  File "/home/runner/workspace/.pythonlibs/lib/python3.12/site-packages/django/core/management/commands/runserver.py", line 134, in inner_run
    self.check(**check_kwargs)
  File "/home/runner/workspace/.pythonlibs/lib/python3.12/site-packages/django/core/management/base.py", line 492, in check
    all_issues = checks.run_checks(
                 ^^^^^^^^^^^^^^^^^^
  File "/home/runner/workspace/.pythonlibs/lib/python3.12/site-packages/django/core/checks/registry.py", line 89, in run_checks
    new_errors = check(app_configs=app_configs, databases=databases)
                 ^^^^^^^^^^^^^^^^^^^^^^^^^^^^^^^^^^^^^^^^^^^^^^^^^^^
  File "/home/runner/workspace/.pythonlibs/lib/python3.12/site-packages/django/core/checks/urls.py", line 136, in check_custom_error_handlers
    handler = resolver.resolve_error_handler(status_code)
              ^^^^^^^^^^^^^^^^^^^^^^^^^^^^^^^^^^^^^^^^^^^
  File "/home/runner/workspace/.pythonlibs/lib/python3.12/site-packages/django/urls/resolvers.py", line 732, in resolve_error_handler
    callback = getattr(self.urlconf_module, "handler%s" % view_type, None)
                       ^^^^^^^^^^^^^^^^^^^
  File "/home/runner/workspace/.pythonlibs/lib/python3.12/site-packages/django/utils/functional.py", line 47, in __get__
    res = instance.__dict__[self.name] = self.func(instance)
                                         ^^^^^^^^^^^^^^^^^^^
  File "/home/runner/workspace/.pythonlibs/lib/python3.12/site-packages/django/urls/resolvers.py", line 711, in urlconf_module
    return import_module(self.urlconf_name)
           ^^^^^^^^^^^^^^^^^^^^^^^^^^^^^^^^
  File "/nix/store/vnvdzw4182wb2ifzi0cczhv80yfnpx1q-python3-3.12.11/lib/python3.12/importlib/__init__.py", line 90, in import_module
    return _bootstrap._gcd_import(name[level:], package, level)
           ^^^^^^^^^^^^^^^^^^^^^^^^^^^^^^^^^^^^^^^^^^^^^^^^^^^^
  File "<frozen importlib._bootstrap>", line 1387, in _gcd_import
  File "<frozen importlib._bootstrap>", line 1360, in _find_and_load
  File "<frozen importlib._bootstrap>", line 1331, in _find_and_load_unlocked
  File "<frozen importlib._bootstrap>", line 935, in _load_unlocked
  File "<frozen importlib._bootstrap_external>", line 999, in exec_module
  File "<frozen importlib._bootstrap>", line 488, in _call_with_frames_removed
  File "/home/runner/workspace/healthstack/urls.py", line 38, in <module>
    path('doctor/', include('doctor.urls')),
                    ^^^^^^^^^^^^^^^^^^^^^^
  File "/home/runner/workspace/.pythonlibs/lib/python3.12/site-packages/django/urls/conf.py", line 39, in include
    urlconf_module = import_module(urlconf_module)
                     ^^^^^^^^^^^^^^^^^^^^^^^^^^^^^
  File "/nix/store/vnvdzw4182wb2ifzi0cczhv80yfnpx1q-python3-3.12.11/lib/python3.12/importlib/__init__.py", line 90, in import_module
    return _bootstrap._gcd_import(name[level:], package, level)
           ^^^^^^^^^^^^^^^^^^^^^^^^^^^^^^^^^^^^^^^^^^^^^^^^^^^^
  File "<frozen importlib._bootstrap>", line 1387, in _gcd_import
  File "<frozen importlib._bootstrap>", line 1360, in _find_and_load
  File "<frozen importlib._bootstrap>", line 1331, in _find_and_load_unlocked
  File "<frozen importlib._bootstrap>", line 935, in _load_unlocked
  File "<frozen importlib._bootstrap_external>", line 999, in exec_module
  File "<frozen importlib._bootstrap>", line 488, in _call_with_frames_removed
  File "/home/runner/workspace/doctor/urls.py", line 38, in <module>
    path('doctor-setup-2fa/', views.doctor_setup_two_factor, name="doctor-setup-2fa"),
                              ^^^^^^^^^^^^^^^^^^^^^^^^^^^^^
AttributeError: module 'doctor.views' has no attribute 'doc